Workbook

Sheet M 09.12 01
B2: Agrumi-Gel s.r.l. | D2: MODULO RILEVAMENTO COSTI E DATI DI PRODUZIONE | K2: M 09.12 01
B4: LOTTO DA PRODURRE | H4: DATA PRODUZIONE
B6: 1. USCITA CELLE
B8: OPERATORE | D8: ORA INIZIO | I8: LOTTO | J8: N° FUSTI | K8: TARA | L8: EFFETTIVI
B9: DATA | D9: ORA FINE
B10: OPERATORE | D10: ORA INIZIO | I10: =IF('M 09.12 03'!B10=0,"",('M 09.12 03'!B10)) | J10: =IF('M 09.12 03'!D10=0,"",('M 09.12 03'!D10)) | K10: =IF('M 09.12 03'!E10=0,"",('M 09.12 03'!E10))
B11: DATA | D11: ORA FINE | I11: =IF('M 09.12 03'!B11=0,"",('M 09.12 03'!B11)) | J11: =IF('M 09.12 03'!D11=0,"",('M 09.12 03'!D11)) | K11: =IF('M 09.12 03'!E11=0,"",('M 09.12 03'!E11))
B12: OPERATORE | D12: ORA INIZIO | I12: =IF('M 09.12 03'!B12=0,"",('M 09.12 03'!B12)) | J12: =IF('M 09.12 03'!D12=0,"",('M 09.12 03'!D12)) | K12: =IF('M 09.12 03'!E12=0,"",('M 09.12 03'!E12))
B13: DATA | D13: ORA FINE | I13: =IF('M 09.12 03'!B13=0,"",('M 09.12 03'!B13)) | J13: =IF('M 09.12 03'!D13=0,"",('M 09.12 03'!D13)) | K13: =IF('M 09.12 03'!E13=0,"",('M 09.12 03'!E13))
B14: OPERATORE | D14: ORA INIZIO | I14: =IF('M 09.12 03'!B14=0,"",('M 09.12 03'!B14)) | J14: =IF('M 09.12 03'!D14=0,"",('M 09.12 03'!D14)) | K14: =IF('M 09.12 03'!E14=0,"",('M 09.12 03'!E14))
B15: DATA | D15: ORA FINE | I15: =IF('M 09.12 03'!B15=0,"",('M 09.12 03'!B15)) | J15: =IF('M 09.12 03'!D15=0,"",('M 09.12 03'!D15)) | K15: =IF('M 09.12 03'!E15=0,"",('M 09.12 03'!E15))
I16: =IF('M 09.12 03'!B16=0,"",('M 09.12 03'!B16)) | J16: =IF('M 09.12 03'!D16=0,"",('M 09.12 03'!D16)) | K16: =IF('M 09.12 03'!E16=0,"",('M 09.12 03'!E16))
I17: =IF('M 09.12 03'!B17=0,"",('M 09.12 03'!B17)) | J17: =IF('M 09.12 03'!D17=0,"",('M 09.12 03'!D17)) | K17: =IF('M 09.12 03'!E17=0,"",('M 09.12 03'!E17))
I18: =IF('M 09.12 03'!B18=0,"",('M 09.12 03'!B18)) | J18: =IF('M 09.12 03'!D18=0,"",('M 09.12 03'!D18)) | K18: =IF('M 09.12 03'!E18=0,"",('M 09.12 03'!E18))
B20: 2. TRASFERIMENTO REAGENTI PER BLENDING
B22: OPERATORE | D22: ORA INIZIO | H22: REAGENTE | I22: LOTTO | J22: N° COLLI | K22: TARA | L22: EFFETTIVI
B23: DATA | D23: ORA FINE
B24: OPERATORE | D24: ORA INIZIO | I24: =IF('M 09.12 03'!#REF!=0,"",('M 09.12 03'!#REF!)) -> #REF! | J24: =IF('M 09.12 03'!#REF!=0,"",('M 09.12 03'!#REF!)) -> #REF! | K24: =IF('M 09.12 03'!#REF!=0,"",('M 09.12 03'!#REF!)) -> #REF!
B25: DATA | D25: ORA FINE | I25: =IF('M 09.12 03'!#REF!=0,"",('M 09.12 03'!#REF!)) -> #REF! | J25: =IF('M 09.12 03'!#REF!=0,"",('M 09.12 03'!#REF!)) -> #REF! | K25: =IF('M 09.12 03'!#REF!=0,"",('M 09.12 03'!#REF!)) -> #REF!
I26: =IF('M 09.12 03'!#REF!=0,"",('M 09.12 03'!#REF!)) -> #REF! | J26: =IF('M 09.12 03'!#REF!=0,"",('M 09.12 03'!#REF!)) -> #REF! | K26: =IF('M 09.12 03'!#REF!=0,"",('M 09.12 03'!#REF!)) -> #REF!
I27: =IF('M 09.12 03'!#REF!=0,"",('M 09.12 03'!#REF!)) -> #REF! | J27: =IF('M 09.12 03'!#REF!=0,"",('M 09.12 03'!#REF!)) -> #REF! | K27: =IF('M 09.12 03'!#REF!=0,"",('M 09.12 03'!#REF!)) -> #REF!
I28: =IF('M 09.12 03'!#REF!=0,"",('M 09.12 03'!#REF!)) -> #REF! | J28: =IF('M 09.12 03'!#REF!=0,"",('M 09.12 03'!#REF!)) -> #REF! | K28: =IF('M 09.12 03'!#REF!=0,"",('M 09.12 03'!#REF!)) -> #REF!
I29: =IF('M 09.12 03'!#REF!=0,"",('M 09.12 03'!#REF!)) -> #REF! | J29: =IF('M 09.12 03'!#REF!=0,"",('M 09.12 03'!#REF!)) -> #REF! | K29: =IF('M 09.12 03'!#REF!=0,"",('M 09.12 03'!#REF!)) -> #REF!
I30: =IF('M 09.12 03'!#REF!=0,"",('M 09.12 03'!#REF!)) -> #REF! | J30: =IF('M 09.12 03'!#REF!=0,"",('M 09.12 03'!#REF!)) -> #REF! | K30: =IF('M 09.12 03'!#REF!=0,"",('M 09.12 03'!#REF!)) -> #REF!
I31: =IF('M 09.12 03'!#REF!=0,"",('M 09.12 03'!#REF!)) -> #REF! | J31: =IF('M 09.12 03'!#REF!=0,"",('M 09.12 03'!#REF!)) -> #REF! | K31: =IF('M 09.12 03'!#REF!=0,"",('M 09.12 03'!#REF!)) -> #REF!
I32: =IF('M 09.12 03'!#REF!=0,"",('M 09.12 03'!#REF!)) -> #REF! | J32: =IF('M 09.12 03'!#REF!=0,"",('M 09.12 03'!#REF!)) -> #REF! | K32: =IF('M 09.12 03'!#REF!=0,"",('M 09.12 03'!#REF!)) -> #REF!
B34: 3. TRASFERIMENTO IMBALLI PER BLENDING
B36: OPERATORE | D36: ORA INIZIO | I36: IMBALLO | J36: MISURA | K36: Q.TA' | L36: EFFETTIVI
B37: DATA | D37: ORA FINE
B38: OPERATORE | D38: ORA INIZIO
B39: DATA | D39: ORA FINE
B44: 3. INGRESSO PRODOTTI FINITI IN CELLA
B46: OPERATORE | D46: ORA INIZIO | F46: N° CELLA | I46: IMBALLO | J46: MISURA | K46: Q.TA' | L46: EFFETTIVI
B47: DATA | D47: ORA FINE | F47: N° FILA
B48: OPERATORE | D48: ORA INIZIO | F48: N° CELLA
B49: DATA | D49: ORA FINE | F49: N° FILA
B53: 4. INGRESSO RIMANENZE IN CELLA
B55: OPERATORE | D55: ORA INIZIO | F55: N° CELLA | I55: IMBALLO | J55: MISURA | K55: Q.TA' | L55: EFFETTIVI
B56: DATA | D56: ORA FINE | F56: N° FILA
B57: OPERATORE | D57: ORA INIZIO | F57: N° CELLA
...

Sheet M 09. 12 02
A1: Agrumi-Gel s.r.l. | C1: MODULO RILEVAMENTO COSTI E DATI DI PRODUZIONE | J1: M 09.12 02
A2: 1. PULIZIA IMPIANTO
A3: PRODOTTI UTILIZZATI | C3: TRITURATORE | E3: TUBAZIONI E QUADRI DI DISTRIBUZIONE | G3: SERBATOI | H3: PRODOTTI FINITI | I3: SCARICO VALVOLA TUNNEL | K3: APERTURA VALVOLA VAPORE
C4: Inizio Produzione | D4: Fine Produzione | E4: Inizio Produzione | F4: Fine Produzione | I4: Inizio Produzione | J4: Fine Produzione | K4: Inizio Produzione | L4: Fine Produzione
A5: DIVOSAN C (Soluzione al 1%)
A6: DIVOSAN FORTE (Soluzione al 0,1%)
A7: Acqua Potabile
A9: OPERATORE | F9: FIRMA
A11: LOTTO DA PRODURRE | G11: DATA PRODUZIONE
A12: 2. PASSAGGIO IN CAMERA CALDA
A13: OPERATORE | C13: ORA INIZIO | E13: T° Camere Calde | G13: OPERATORE | J13: ORA INIZIO
A15: DATA | C15: ORA FINE | E15: T° Camere Calde | G15: DATA | J15: ORA FINE
A17: 3. VERIFICA INIZIALE FILTRO
A18: OPERATORE | C18: PULIZIA | D18: SI □ NO □
A19: DATA | C19: INTEGRITA' | D19: SI □ NO □
A20: 4. TRITURAZIONE
A21: OPERATORE | C21: ORA INIZIO | G21: OPERATORE | J21: ORA INIZIO
A22: DATA | C22: ORA FINE | G22: DATA | J22: ORA FINE
A24: OPERATORE | C24: ORA INIZIO | G24: OPERATORE | J24: ORA INIZIO
A25: DATA | C25: ORA FINE | G25: DATA | J25: ORA FINE
A26: 5. VERIFICA FINALE FILTRO
A27: OPERATORE | C27: PULIZIA | D27: SI □ NO □
A28: DATA | C28: INTEGRITA' | D28: SI □ NO □
A29: 6. SISTEMAZIONE FUSTI
A30: OPERATORE | C30: ORA INIZIO | G30: OPERATORE | J30: ORA INIZIO
A31: DATA | C31: ORA FINE | G31: DATA | J31: ORA FINE
A33: 12 | B33: 44432 | D33: Nuovo Amministratore | I33: LOREDANA DE FRANCESCO | K33: RIZZO SALVATORE
A34: REV. | B34: DATA | D34: MOTIVO DELLA REVISIONE | I34: EMESSO DA: | K34: APPROVATO DA:

Sheet M 09.12 03
B2: Agrumi-Gel s.r.l. | D2: MODULO RILEVAMENTO COSTI E DATI DI PRODUZIONE | P2: M 09.12 03
B4: PRODOTTO | D4: UNPATEURIZED LEMON JUICE NFC | J4: CLIENTE | L4: BOIRON | N4: DATA PRODUZIONE | P4: 44441
B5: KG. | D5: 20800 | E5: LOTTO | F5: SLN 21/21 PF | H5: CAMPIONE N° | O5: TINI UTILIZZATI | Q5: 1
D7: Q.TA' PREVISTA | G7: Q.TA' EFFETTIVA | J7: TINO 1 | L7: TINO 2 | N7: TINO 3 | P7: TINO 4
B8: LOTTO PRODOTTO | D8: N° FUSTI | E8: TARA | F8: TOT. | G8: N° FUSTI | H8: TARA | I8: TOT. | J8: PREVENTIVO | K8: EFFETTIVO | L8: PREVENTIVO | M8: EFFETTIVO | N8: PREVENTIVO | O8: EFFETTIVO | P8: PREVENTIVO | Q8: EFFETTIVO
B9: SLN 68/20 | D9: 104 | E9: 200 | F9: =(D9*E9) -> 20800 | G9: 104 | H9: 200 | I9: =(G9*H9) -> 20800 | J9: 20800 | K9: 20800 | L9: =IF($Q$5>1,F9/$Q$5,"") | M9: =IF($Q$5>1,I9/$Q$5,"") | N9: =IF($Q$5>2,F9/$Q$5,"") | O9: =IF($Q$5>2,I9/$Q$5,"") | P9: =IF($Q$5>3,F9/$Q$5,"") | Q9: =IF($Q$5>3,I9/$Q$5,"")
F10: =(D10*E10) -> 0 | I10: =(G10*H10) -> 0 | L10: =IF($Q$5>1,F10/$Q$5,"") | M10: =IF($Q$5>1,I10/$Q$5,"") | N10: =IF($Q$5>2,F10/$Q$5,"") | O10: =IF($Q$5>2,I10/$Q$5,"") | P10: =IF($Q$5>3,F10/$Q$5,"") | Q10: =IF($Q$5>3,I10/$Q$5,"")
F11: =(D11*E11) -> 0 | I11: =(G11*H11) -> 0 | L11: =IF($Q$5>1,F11/$Q$5,"") | M11: =IF($Q$5>1,I11/$Q$5,"") | N11: =IF($Q$5>2,F11/$Q$5,"") | O11: =IF($Q$5>2,I11/$Q$5,"") | P11: =IF($Q$5>3,F11/$Q$5,"") | Q11: =IF($Q$5>3,I11/$Q$5,"")
F12: =(D12*E12) -> 0 | I12: =(G12*H12) -> 0 | L12: =IF($Q$5>1,F12/$Q$5,"") | M12: =IF($Q$5>1,I12/$Q$5,"") | N12: =IF($Q$5>2,F12/$Q$5,"") | O12: =IF($Q$5>2,I12/$Q$5,"") | P12: =IF($Q$5>3,F12/$Q$5,"") | Q12: =IF($Q$5>3,I12/$Q$5,"")
F13: =(D13*E13) -> 0 | I13: =(G13*H13) -> 0 | L13: =IF($Q$5>1,F13/$Q$5,"") | M13: =IF($Q$5>1,I13/$Q$5,"") | N13: =IF($Q$5>2,F13/$Q$5,"") | O13: =IF($Q$5>2,I13/$Q$5,"") | P13: =IF($Q$5>3,F13/$Q$5,"") | Q13: =IF($Q$5>3,I13/$Q$5,"")
F14: =(D14*E14) -> 0 | I14: =(G14*H14) -> 0 | J14: =IF($Q$5=0,"",(F14/$Q$5)) -> 0 | K14: =IF($Q$5=0,"",(I14/$Q$5)) -> 0 | L14: =IF($Q$5>1,F14/$Q$5,"") | M14: =IF($Q$5>1,I14/$Q$5,"") | N14: =IF($Q$5>2,F14/$Q$5,"") | O14: =IF($Q$5>2,I14/$Q$5,"") | P14: =IF($Q$5>3,F14/$Q$5,"") | Q14: =IF($Q$5>3,I14/$Q$5,"")
F15: =(D15*E15) -> 0 | I15: =(G15*H15) -> 0 | J15: =IF($Q$5=0,"",(F15/$Q$5)) -> 0 | K15: =IF($Q$5=0,"",(I15/$Q$5)) -> 0 | L15: =IF($Q$5>1,F15/$Q$5,"") | M15: =IF($Q$5>1,I15/$Q$5,"") | N15: =IF($Q$5>2,F15/$Q$5,"") | O15: =IF($Q$5>2,I15/$Q$5,"") | P15: =IF($Q$5>3,F15/$Q$5,"") | Q15: =IF($Q$5>3,I15/$Q$5,"")
F16: =(D16*E16) -> 0 | I16: =(G16*H16) -> 0 | J16: =IF($Q$5=0,"",(F16/$Q$5)) -> 0 | K16: =IF($Q$5=0,"",(I16/$Q$5)) -> 0 | L16: =IF($Q$5>1,F16/$Q$5,"") | M16: =IF($Q$5>1,I16/$Q$5,"") | N16: =IF($Q$5>2,F16/$Q$5,"") | O16: =IF($Q$5>2,I16/$Q$5,"") | P16: =IF($Q$5>3,F16/$Q$5,"") | Q16: =IF($Q$5>3,I16/$Q$5,"")
F17: =(D17*E17) -> 0 | I17: =(G17*H17) -> 0 | J17: =IF($Q$5=0,"",(F17/$Q$5)) -> 0 | K17: =IF($Q$5=0,"",(I17/$Q$5)) -> 0 | L17: =IF($Q$5>1,F17/$Q$5,"") | M17: =IF($Q$5>1,I17/$Q$5,"") | N17: =IF($Q$5>2,F17/$Q$5,"") | O17: =IF($Q$5>2,I17/$Q$5,"") | P17: =IF($Q$5>3,F17/$Q$5,"") | Q17: =IF($Q$5>3,I17/$Q$5,"")
F18: =(D18*E18) -> 0 | I18: =(G18*H18) -> 0 | J18: =IF($Q$5=0,"",(F18/$Q$5)) -> 0 | K18: =IF($Q$5=0,"",(I18/$Q$5)) -> 0 | L18: =IF($Q$5>1,F18/$Q$5,"") | M18: =IF($Q$5>1,I18/$Q$5,"") | N18: =IF($Q$5>2,F18/$Q$5,"") | O18: =IF($Q$5>2,I18/$Q$5,"") | P18: =IF($Q$5>3,F18/$Q$5,"") | Q18: =IF($Q$5>3,I18/$Q$5,"")
B19: TOTALE | D19: =SUM(D9:D18) -> 104 | E19: =SUM(E9:E18) -> 200 | F19: =SUM(F9:F18) -> 20800 | G19: =SUM(G9:G18) -> 104 | H19: =SUM(H9:H18) -> 200 | I19: =SUM(I9:I18) -> 20800 | J19: =SUM(J9:J18) -> 20800 | K19: =SUM(K9:K18) -> 20800 | ... Q19: =SUM(Q9:Q18) -> 0
B21: N° | E21: CONFEZIONATI COME PF | H21: RIMANENZA CONFEZIONATA IN N° | N21: LAVAGGIO IN N° | Q21: FUSTI
B23: ISTRUZIONI PER IL CONFEZIONAMENTO
B24: TIPO IMBALLO | D24: FUSTO TRONCO | F24: DA | G24: 200 | H24: KG. NETTI CADAUNO | K24: CON N° | M24: SACCHI | N24: TIPO | P24: TIPO
B25: LOTTO IMBALLO | M25: LOTTO SACCHI
B26: APPORRE N° | D26: 1 | E26: ETICHETTE PER OGNI | H26: =IF(D24=0,"",(D24)) -> FUSTO TRONCO | J26: SISTEMARE IL CARICO SU N° | N26: PALLET | O26: 2 VIE | P26: MISURA | Q26: 110X120
B27: REGETTA | D27: SI | F27: VELOFILM | H27: SI | J27: SIGILLI
B29: NOTE
B32: PARTE DA COMPILARE A CURA DELL' ADDETTO PRODOTTI FINITI
B33: 1. PREPARAZIONE BLENDING | E33: OPERATORE 1: | I33: DATA | K33: DALLE ORE: | M33: ALLE ORE: | O33: PH BLENDING: | Q33: 2.58
E34: OPERATORE 2: | I34: DATA | K34: DALLE ORE: | M34: ALLE ORE:
B36: 2. AGGIUNTA PRODOTTI | E36: OPERATORE 1: | I36: DATA | L36: DALLE ORE: | O36: ALLE ORE:
E37: OPERATORE 2: | I37: DATA | L37: DALLE ORE: | O37: ALLE ORE:
B39: PULIZIA FILTRO SI INIZIALE NO | D39: FIRMA OPERATORE | F39: PRESENZA COPRI ESTRANEI SI NEL FILTRO POSTFILTRAZIONE NO | I39: FIRMA OPERATORE | L39: TIPO FILTRO: | N39: FORATA: | O39: mm | P39: *IN CASO DI FILTRAZIONE CON FILTRO MILLIPORE ALLEGARE SCONTRINO INTEGRITY TEST
B40: PULIZIA FILTRO SI FINALE NO | D40: FIRMA OPERATORE | F40: In caso di presenza di corpi estranei nel filtro postfiltrazione far pervenire il copro estranei a LAB per identificazione | L40: PRESSIONE D'ESERCIZIO INIZIALE | O40: PRESSIONE D'ESERCIZIO FINALE
B42: CCP 2 INTEGRITA' SI FILTRO INIZIALE NO | D42: DATA | F42: ORA | H42: FIRMA OPERATORE | L42: FIRMA RESPONSABILE
B43: CCP 2 INTEGRITA' SI FILTRO FINALE NO | D43: DATA | F43: ORA | H43: FIRMA OPERATORE | L43: DATA, ORA E FIRMA AVVENUTO CONTROLLO
B45: 16 | C45: 44432 | D45: NUOVO AMMINISTRATORE | N45: LOREDANA DE FRANCESCO | P45: RIZZO SALVATORE
B46: REV. | C46: DATA | D46: MOTIVO DELLA REVISIONE | N46: EMESSO DA: | P46: APPROVATO DA:

Sheet M 09.12 04
B2: Agrumi-Gel s.r.l. | D2: MODULO RILEVAMENTO COSTI E DATI DI PRODUZIONE | J2: M 09.12 04
B4: LOTTO DA PRODURRE | F4: DATA PRODUZIONE
B6: 1. TIRAGGIO FUSTI
B8: OPERATORE | D8: ORA INIZIO | G8: OPERATORE | J8: ORA INIZIO
B9: DATA | D9: ORA FINE | G9: DATA | J9: ORA FINE
B11: 2. PREPARAZIONE BLENDING
B13: OPERATORE | D13: ORA INIZIO | G13: ADDITIVO | I13: LOTTO | J13: QUANTITA'
B14: DATA | D14: ORA FINE | G14: FLOCCULANTE
B15: OPERATORE | D15: ORA INIZIO | G15: CONSERVANTE
B16: DATA | D16: ORA FINE | G16: ENZIMA
B17: OPERATORE | D17: ORA INIZIO
B18: DATA | D18: ORA FINE
B19: OPERATORE | D19: ORA INIZIO
B20: DATA | D20: ORA FINE
B22: 3. PANNELLO FILTRAGGIO TAYLO
B24: OPERATORE | D24: ORA INIZIO | G24: ADDITIVO | I24: LOTTO | J24: QUANTITA'
B25: DATA | D25: ORA FINE | G25: FARINA
B26: OPERATORE | D26: ORA INIZIO | G26: FARINA
B27: DATA | D27: ORA FINE | G27: FARINA
B28: OPERATORE | D28: ORA INIZIO | G28: =IF('M 09.12 03'!#REF!=0,"",('M 09.12 03'!#REF!)) -> #REF! | H28: =IF('M 09.12 03'!#REF!=0,"",('M 09.12 03'!#REF!)) -> #REF! | J28: =IF('M 09.12 03'!#REF!=0,"",('M 09.12 03'!#REF!)) -> #REF!
B29: DATA | D29: ORA FINE | G29: =IF('M 09.12 03'!#REF!=0,"",('M 09.12 03'!#REF!)) -> #REF! | H29: =IF('M 09.12 03'!#REF!=0,"",('M 09.12 03'!#REF!)) -> #REF! | J29: =IF('M 09.12 03'!#REF!=0,"",('M 09.12 03'!#REF!)) -> #REF!
G30: =IF('M 09.12 03'!#REF!=0,"",('M 09.12 03'!#REF!)) -> #REF! | H30: =IF('M 09.12 03'!#REF!=0,"",('M 09.12 03'!#REF!)) -> #REF! | J30: =IF('M 09.12 03'!#REF!=0,"",('M 09.12 03'!#REF!)) -> #REF!
B31: 4. ULTRAFILTRAZIONE
B33: OPERATORE | D33: ORA INIZIO | G33: OPERATORE | J33: ORA INIZIO
B34: DATA | D34: ORA FINE | G34: DATA | J34: ORA FINE
B36: 10 | C36: 44432 | D36: NUOVO AMMINISTRATORE | H36: LOREDANA DE FRANCESCO | K36: RIZZO SALVATORE
B37: REV. | C37: DATA | D37: MOTIVO DELLA REVISIONE | H37: EMESSO DA: | K37: APPROVATO DA:

Sheet M 09.12 05
B2: Agrumi-Gel s.r.l. | D2: MODULO RILEVAMENTO COSTI PREPARAZIONE FUSTI PER LO SCARICO | I2: M 09.12 05
B4: PERSONALE UTILIZZATO | F4: DATA PRODUZIONE
B6: PREPARAZIONE FUSTI PER LO SCARICO
B8: OPERATORE 1 | D8: ORA INIZIO
B9: DATA | D9: ORA FINE
B10: TIPO E NUMERO FUSTO | C10: NUOVO o NUMERO……………... | D10: USATO o NUMERO ………….. | E10: LOTTO FUSTO N°……………….
B11: TIPO SACCHI | C11: NUOVO o NUMERO……………... | D11: FORNITORE SACCHI ……………. | E11: LOTTO SACCHI N°………………………..
B12: N° PEDANE | C12: NUOVO o NUMERO……………... | D12: USATO o NUMERO ………….. | E12: LOTTO PEDANE N°………………………..
B14: OPERATORE 2 | D14: ORA INIZIO
B15: DATA | D15: ORA FINE
B16: TIPO E NUMERO FUSTO | C16: NUOVO o NUMERO……………... | D16: USATO o NUMERO ………….. | E16: LOTTO FUSTO N°……………….
B17: TIPO SACCHI | C17: NUOVO o NUMERO……………... | D17: FORNITORE SACCHI ……………. | E17: LOTTO SACCHI N°………………………..
B18: N° PEDANE | C18: NUOVO o NUMERO……………... | D18: USATO o NUMERO ………….. | E18: LOTTO PEDANE N°………………………..
B20: OPERATORE 3 | D20: ORA INIZIO
B21: DATA | D21: ORA FINE
B22: TIPO E NUMERO FUSTO | C22: NUOVO o NUMERO……………... | D22: USATO o NUMERO ………….. | E22: LOTTO FUSTO N°……………….
B23: TIPO SACCHI | C23: NUOVO o NUMERO……………... | D23: FORNITORE SACCHI ……………. | E23: LOTTO SACCHI N°………………………..
B24: N° PEDANE | C24: NUOVO o NUMERO……………... | D24: USATO o NUMERO ………….. | E24: LOTTO PEDANE N°……………………….. | G24: =IF('M 09.12 03'!#REF!=0,"",('M 09.12 03'!#REF!)) -> #REF! | H24: =IF('M 09.12 03'!#REF!=0,"",('M 09.12 03'!#REF!)) -> #REF! | I24: =IF('M 09.12 03'!#REF!=0,"",('M 09.12 03'!#REF!)) -> #REF!
B26: OPERATORE 4 | D26: ORA INIZIO
B27: DATA | D27: ORA FINE
B28: TIPO E NUMERO FUSTO | C28: NUOVO o NUMERO……………... | D28: USATO o NUMERO ………….. | E28: LOTTO FUSTO N°……………….
B29: TIPO SACCHI | C29: NUOVO o NUMERO……………... | D29: FORNITORE SACCHI ……………. | E29: LOTTO SACCHI N°………………………..
B30: N° PEDANE | C30: NUOVO o NUMERO……………... | D30: USATO o NUMERO ………….. | E30: LOTTO PEDANE N°………………………..
B34: NOTA: IN MEDIA NEL TEMPO DI 5 ORE N° 2 PERSONE REALIZZANO N° 50 PEDANE CON FUSTI NUOVI O N. 40 PEDANE CON FUSTI USATI
B36: 1 | C36: 42982 | D36: INSERITE SPECIFICHE PER NUMERO LOTTI IMBALLI | H36: MARIA ISGRO' | I36: SALVATORE IMBESI | J36: SALVATORE IMBESI
B37: REV. | C37: DATA | D37: MOTIVO DELLA REVISIONE | H37: EMESSO DA: | I37: APPROVATO DA: | J37: APPROVATO DA:
